[2025-03-21T16:42:55.256+0500] {local_task_job_runner.py:123} INFO - ::group::Pre task execution logs
[2025-03-21T16:42:55.267+0500] {taskinstance.py:2614} INFO - Dependencies all met for dep_context=non-requeueable deps ti=<TaskInstance: fetch_serapi.fetch_serapi_images manual__2025-03-21T11:42:51.398522+00:00 [queued]>
[2025-03-21T16:42:55.274+0500] {taskinstance.py:2614} INFO - Dependencies all met for dep_context=requeueable deps ti=<TaskInstance: fetch_serapi.fetch_serapi_images manual__2025-03-21T11:42:51.398522+00:00 [queued]>
[2025-03-21T16:42:55.274+0500] {taskinstance.py:2867} INFO - Starting attempt 1 of 1
[2025-03-21T16:42:55.290+0500] {taskinstance.py:2890} INFO - Executing <Task(PythonOperator): fetch_serapi_images> on 2025-03-21 11:42:51.398522+00:00
[2025-03-21T16:42:55.295+0500] {standard_task_runner.py:72} INFO - Started process 34949 to run task
[2025-03-21T16:42:55.299+0500] {standard_task_runner.py:104} INFO - Running: ['airflow', 'tasks', 'run', 'fetch_serapi', 'fetch_serapi_images', 'manual__2025-03-21T11:42:51.398522+00:00', '--job-id', '8', '--raw', '--subdir', 'DAGS_FOLDER/fetch_serapi.py', '--cfg-path', '/tmp/tmpl4_63fk3']
[2025-03-21T16:42:55.300+0500] {standard_task_runner.py:105} INFO - Job 8: Subtask fetch_serapi_images
[2025-03-21T16:42:55.337+0500] {task_command.py:467} INFO - Running <TaskInstance: fetch_serapi.fetch_serapi_images manual__2025-03-21T11:42:51.398522+00:00 [running]> on host ubuntu
[2025-03-21T16:42:55.402+0500] {taskinstance.py:3134} INFO - Exporting env vars: AIRFLOW_CTX_DAG_OWNER='airflow' AIRFLOW_CTX_DAG_ID='fetch_serapi' AIRFLOW_CTX_TASK_ID='fetch_serapi_images' AIRFLOW_CTX_EXECUTION_DATE='2025-03-21T11:42:51.398522+00:00' AIRFLOW_CTX_TRY_NUMBER='1' AIRFLOW_CTX_DAG_RUN_ID='manual__2025-03-21T11:42:51.398522+00:00'
[2025-03-21T16:42:55.403+0500] {logging_mixin.py:190} INFO - Task instance is in running state
[2025-03-21T16:42:55.404+0500] {logging_mixin.py:190} INFO -  Previous state of the Task instance: queued
[2025-03-21T16:42:55.404+0500] {logging_mixin.py:190} INFO - Current task name:fetch_serapi_images state:running start_date:2025-03-21 11:42:55.267767+00:00
[2025-03-21T16:42:55.404+0500] {logging_mixin.py:190} INFO - Dag name:fetch_serapi and current dag run status:running
[2025-03-21T16:42:55.404+0500] {taskinstance.py:732} INFO - ::endgroup::
[2025-03-21T16:42:55.812+0500] {taskinstance.py:3313} ERROR - Task failed with exception
Traceback (most recent call last):
  File "/home/tashi/.local/lib/python3.10/site-packages/requests/models.py", line 974, in json
    return complexjson.loads(self.text, **kwargs)
  File "/usr/lib/python3.10/json/__init__.py", line 346, in loads
    return _default_decoder.decode(s)
  File "/usr/lib/python3.10/json/decoder.py", line 337, in decode
    obj, end = self.raw_decode(s, idx=_w(s, 0).end())
  File "/usr/lib/python3.10/json/decoder.py", line 355, in raw_decode
    raise JSONDecodeError("Expecting value", s, err.value) from None
json.decoder.JSONDecodeError: Expecting value: line 1 column 1 (char 0)

During handling of the above exception, another exception occurred:

Traceback (most recent call last):
  File "/home/tashi/.local/lib/python3.10/site-packages/airflow/models/taskinstance.py", line 768, in _execute_task
    result = _execute_callable(context=context, **execute_callable_kwargs)
  File "/home/tashi/.local/lib/python3.10/site-packages/airflow/models/taskinstance.py", line 734, in _execute_callable
    return ExecutionCallableRunner(
  File "/home/tashi/.local/lib/python3.10/site-packages/airflow/utils/operator_helpers.py", line 252, in run
    return self.func(*args, **kwargs)
  File "/home/tashi/.local/lib/python3.10/site-packages/airflow/models/baseoperator.py", line 424, in wrapper
    return func(self, *args, **kwargs)
  File "/home/tashi/.local/lib/python3.10/site-packages/airflow/operators/python.py", line 238, in execute
    return_value = self.execute_callable()
  File "/home/tashi/.local/lib/python3.10/site-packages/airflow/operators/python.py", line 256, in execute_callable
    return runner.run(*self.op_args, **self.op_kwargs)
  File "/home/tashi/.local/lib/python3.10/site-packages/airflow/utils/operator_helpers.py", line 252, in run
    return self.func(*args, **kwargs)
  File "/home/tashi/airflow/dags/fetch_serapi.py", line 10, in fetch_serapi_traffic_images
    data = response.json()
  File "/home/tashi/.local/lib/python3.10/site-packages/requests/models.py", line 978, in json
    raise RequestsJSONDecodeError(e.msg, e.doc, e.pos)
requests.exceptions.JSONDecodeError: Expecting value: line 1 column 1 (char 0)
[2025-03-21T16:42:55.826+0500] {logging_mixin.py:190} INFO - Task instance in failure state
[2025-03-21T16:42:55.827+0500] {logging_mixin.py:190} INFO - Task start:2025-03-21 11:42:55.267767+00:00 end:2025-03-21 11:42:55.825415+00:00 duration:0.557648
[2025-03-21T16:42:55.827+0500] {logging_mixin.py:190} INFO - Task:<Task(PythonOperator): fetch_serapi_images> dag:<DAG: fetch_serapi> dagrun:<DagRun fetch_serapi @ 2025-03-21 11:42:51.398522+00:00: manual__2025-03-21T11:42:51.398522+00:00, state:running, queued_at: 2025-03-21 11:42:51.418314+00:00. externally triggered: True>
[2025-03-21T16:42:55.828+0500] {logging_mixin.py:190} INFO - Failure caused by Expecting value: line 1 column 1 (char 0)
[2025-03-21T16:42:55.828+0500] {taskinstance.py:1226} INFO - Marking task as FAILED. dag_id=fetch_serapi, task_id=fetch_serapi_images, run_id=manual__2025-03-21T11:42:51.398522+00:00, execution_date=20250321T114251, start_date=20250321T114255, end_date=20250321T114255
[2025-03-21T16:42:55.860+0500] {taskinstance.py:341} INFO - ::group::Post task execution logs
[2025-03-21T16:42:55.860+0500] {standard_task_runner.py:124} ERROR - Failed to execute job 8 for task fetch_serapi_images (Expecting value: line 1 column 1 (char 0); 34949)
Traceback (most recent call last):
  File "/home/tashi/.local/lib/python3.10/site-packages/requests/models.py", line 974, in json
    return complexjson.loads(self.text, **kwargs)
  File "/usr/lib/python3.10/json/__init__.py", line 346, in loads
    return _default_decoder.decode(s)
  File "/usr/lib/python3.10/json/decoder.py", line 337, in decode
    obj, end = self.raw_decode(s, idx=_w(s, 0).end())
  File "/usr/lib/python3.10/json/decoder.py", line 355, in raw_decode
    raise JSONDecodeError("Expecting value", s, err.value) from None
json.decoder.JSONDecodeError: Expecting value: line 1 column 1 (char 0)

During handling of the above exception, another exception occurred:

Traceback (most recent call last):
  File "/home/tashi/.local/lib/python3.10/site-packages/airflow/task/task_runner/standard_task_runner.py", line 117, in _start_by_fork
    ret = args.func(args, dag=self.dag)
  File "/home/tashi/.local/lib/python3.10/site-packages/airflow/cli/cli_config.py", line 49, in command
    return func(*args, **kwargs)
  File "/home/tashi/.local/lib/python3.10/site-packages/airflow/utils/cli.py", line 116, in wrapper
    return f(*args, **kwargs)
  File "/home/tashi/.local/lib/python3.10/site-packages/airflow/cli/commands/task_command.py", line 483, in task_run
    task_return_code = _run_task_by_selected_method(args, _dag, ti)
  File "/home/tashi/.local/lib/python3.10/site-packages/airflow/cli/commands/task_command.py", line 256, in _run_task_by_selected_method
    return _run_raw_task(args, ti)
  File "/home/tashi/.local/lib/python3.10/site-packages/airflow/cli/commands/task_command.py", line 341, in _run_raw_task
    return ti._run_raw_task(
  File "/home/tashi/.local/lib/python3.10/site-packages/airflow/utils/session.py", line 97, in wrapper
    return func(*args, session=session, **kwargs)
  File "/home/tashi/.local/lib/python3.10/site-packages/airflow/models/taskinstance.py", line 3006, in _run_raw_task
    return _run_raw_task(
  File "/home/tashi/.local/lib/python3.10/site-packages/airflow/models/taskinstance.py", line 274, in _run_raw_task
    TaskInstance._execute_task_with_callbacks(
  File "/home/tashi/.local/lib/python3.10/site-packages/airflow/models/taskinstance.py", line 3161, in _execute_task_with_callbacks
    result = self._execute_task(context, task_orig)
  File "/home/tashi/.local/lib/python3.10/site-packages/airflow/models/taskinstance.py", line 3185, in _execute_task
    return _execute_task(self, context, task_orig)
  File "/home/tashi/.local/lib/python3.10/site-packages/airflow/models/taskinstance.py", line 768, in _execute_task
    result = _execute_callable(context=context, **execute_callable_kwargs)
  File "/home/tashi/.local/lib/python3.10/site-packages/airflow/models/taskinstance.py", line 734, in _execute_callable
    return ExecutionCallableRunner(
  File "/home/tashi/.local/lib/python3.10/site-packages/airflow/utils/operator_helpers.py", line 252, in run
    return self.func(*args, **kwargs)
  File "/home/tashi/.local/lib/python3.10/site-packages/airflow/models/baseoperator.py", line 424, in wrapper
    return func(self, *args, **kwargs)
  File "/home/tashi/.local/lib/python3.10/site-packages/airflow/operators/python.py", line 238, in execute
    return_value = self.execute_callable()
  File "/home/tashi/.local/lib/python3.10/site-packages/airflow/operators/python.py", line 256, in execute_callable
    return runner.run(*self.op_args, **self.op_kwargs)
  File "/home/tashi/.local/lib/python3.10/site-packages/airflow/utils/operator_helpers.py", line 252, in run
    return self.func(*args, **kwargs)
  File "/home/tashi/airflow/dags/fetch_serapi.py", line 10, in fetch_serapi_traffic_images
    data = response.json()
  File "/home/tashi/.local/lib/python3.10/site-packages/requests/models.py", line 978, in json
    raise RequestsJSONDecodeError(e.msg, e.doc, e.pos)
requests.exceptions.JSONDecodeError: Expecting value: line 1 column 1 (char 0)
[2025-03-21T16:42:55.873+0500] {local_task_job_runner.py:266} INFO - Task exited with return code 1
[2025-03-21T16:42:55.886+0500] {taskinstance.py:3901} INFO - 0 downstream tasks scheduled from follow-on schedule check
[2025-03-21T16:42:55.887+0500] {local_task_job_runner.py:245} INFO - ::endgroup::
